[2025-06-25T01:30:54.752+0000] {local_task_job_runner.py:120} INFO - ::group::Pre task execution logs
[2025-06-25T01:30:54.857+0000] {taskinstance.py:2073} INFO - Dependencies all met for dep_context=non-requeueable deps ti=<TaskInstance: clinlytix360_pipeline.run_survival_analysis manual__2025-06-25T01:21:03.001484+00:00 [queued]>
[2025-06-25T01:30:54.880+0000] {taskinstance.py:2073} INFO - Dependencies all met for dep_context=requeueable deps ti=<TaskInstance: clinlytix360_pipeline.run_survival_analysis manual__2025-06-25T01:21:03.001484+00:00 [queued]>
[2025-06-25T01:30:54.882+0000] {taskinstance.py:2303} INFO - Starting attempt 2 of 2
[2025-06-25T01:30:54.951+0000] {taskinstance.py:2327} INFO - Executing <Task(BashOperator): run_survival_analysis> on 2025-06-25 01:21:03.001484+00:00
[2025-06-25T01:30:54.994+0000] {warnings.py:110} WARNING - /home/***/.local/lib/python3.12/site-packages/***/task/task_runner/standard_task_runner.py:61: DeprecationWarning: This process (pid=193) is multi-threaded, use of fork() may lead to deadlocks in the child.
  pid = os.fork()

[2025-06-25T01:30:55.003+0000] {standard_task_runner.py:63} INFO - Started process 197 to run task
[2025-06-25T01:30:54.998+0000] {standard_task_runner.py:90} INFO - Running: ['***', 'tasks', 'run', 'clinlytix360_pipeline', 'run_survival_analysis', 'manual__2025-06-25T01:21:03.001484+00:00', '--job-id', '17', '--raw', '--subdir', 'DAGS_FOLDER/clinlytix_dag.py', '--cfg-path', '/tmp/tmp_av99z51']
[2025-06-25T01:30:55.010+0000] {standard_task_runner.py:91} INFO - Job 17: Subtask run_survival_analysis
[2025-06-25T01:30:55.312+0000] {task_command.py:426} INFO - Running <TaskInstance: clinlytix360_pipeline.run_survival_analysis manual__2025-06-25T01:21:03.001484+00:00 [running]> on host 6b66237045bc
[2025-06-25T01:30:55.944+0000] {taskinstance.py:2644} INFO - Exporting env vars: AIRFLOW_CTX_DAG_OWNER='ajayc' AIRFLOW_CTX_DAG_ID='clinlytix360_pipeline' AIRFLOW_CTX_TASK_ID='run_survival_analysis' AIRFLOW_CTX_EXECUTION_DATE='2025-06-25T01:21:03.001484+00:00' AIRFLOW_CTX_TRY_NUMBER='2' AIRFLOW_CTX_DAG_RUN_ID='manual__2025-06-25T01:21:03.001484+00:00'
[2025-06-25T01:30:55.960+0000] {taskinstance.py:430} INFO - ::endgroup::
[2025-06-25T01:30:55.977+0000] {subprocess.py:63} INFO - Tmp dir root location: /tmp
[2025-06-25T01:30:55.997+0000] {subprocess.py:75} INFO - Running command: ['/usr/bin/bash', '-c', 'python /opt/***/data/scripts/modeling/survival_analysis.py']
[2025-06-25T01:30:56.057+0000] {subprocess.py:86} INFO - Output:
[2025-06-25T01:30:59.859+0000] {subprocess.py:93} INFO - Traceback (most recent call last):
[2025-06-25T01:30:59.862+0000] {subprocess.py:93} INFO -   File "/opt/***/data/scripts/modeling/survival_analysis.py", line 2, in <module>
[2025-06-25T01:30:59.874+0000] {subprocess.py:93} INFO -     import matplotlib.pyplot as plt
[2025-06-25T01:30:59.876+0000] {subprocess.py:93} INFO - ModuleNotFoundError: No module named 'matplotlib'
[2025-06-25T01:31:00.151+0000] {subprocess.py:97} INFO - Command exited with return code 1
[2025-06-25T01:31:00.153+0000] {taskinstance.py:441} INFO - ::group::Post task execution logs
[2025-06-25T01:31:00.189+0000] {taskinstance.py:2890} ERROR - Task failed with exception
Traceback (most recent call last):
  File "/home/airflow/.local/lib/python3.12/site-packages/airflow/models/taskinstance.py", line 465, in _execute_task
    result = _execute_callable(context=context, **execute_callable_kwargs)
             ^^^^^^^^^^^^^^^^^^^^^^^^^^^^^^^^^^^^^^^^^^^^^^^^^^^^^^^^^^^^^
  File "/home/airflow/.local/lib/python3.12/site-packages/airflow/models/taskinstance.py", line 432, in _execute_callable
    return execute_callable(context=context, **execute_callable_kwargs)
           ^^^^^^^^^^^^^^^^^^^^^^^^^^^^^^^^^^^^^^^^^^^^^^^^^^^^^^^^^^^^
  File "/home/airflow/.local/lib/python3.12/site-packages/airflow/models/baseoperator.py", line 400, in wrapper
    return func(self, *args, **kwargs)
           ^^^^^^^^^^^^^^^^^^^^^^^^^^^
  File "/home/airflow/.local/lib/python3.12/site-packages/airflow/operators/bash.py", line 243, in execute
    raise AirflowException(
airflow.exceptions.AirflowException: Bash command failed. The command returned a non-zero exit code 1.
[2025-06-25T01:31:00.208+0000] {taskinstance.py:1205} INFO - Marking task as FAILED. dag_id=clinlytix360_pipeline, task_id=run_survival_analysis, execution_date=20250625T012103, start_date=20250625T013054, end_date=20250625T013100
[2025-06-25T01:31:00.256+0000] {standard_task_runner.py:110} ERROR - Failed to execute job 17 for task run_survival_analysis (Bash command failed. The command returned a non-zero exit code 1.; 197)
[2025-06-25T01:31:00.307+0000] {local_task_job_runner.py:240} INFO - Task exited with return code 1
[2025-06-25T01:31:00.361+0000] {taskinstance.py:3482} INFO - 0 downstream tasks scheduled from follow-on schedule check
[2025-06-25T01:31:00.373+0000] {local_task_job_runner.py:222} INFO - ::endgroup::
