[2025-06-25T01:06:52.934+0000] {local_task_job_runner.py:120} INFO - ::group::Pre task execution logs
[2025-06-25T01:06:53.053+0000] {taskinstance.py:2073} INFO - Dependencies all met for dep_context=non-requeueable deps ti=<TaskInstance: clinlytix360_pipeline.run_etl_cleaning manual__2025-06-25T01:05:34.728263+00:00 [queued]>
[2025-06-25T01:06:53.086+0000] {taskinstance.py:2073} INFO - Dependencies all met for dep_context=requeueable deps ti=<TaskInstance: clinlytix360_pipeline.run_etl_cleaning manual__2025-06-25T01:05:34.728263+00:00 [queued]>
[2025-06-25T01:06:53.089+0000] {taskinstance.py:2303} INFO - Starting attempt 2 of 2
[2025-06-25T01:06:53.153+0000] {taskinstance.py:2327} INFO - Executing <Task(BashOperator): run_etl_cleaning> on 2025-06-25 01:05:34.728263+00:00
[2025-06-25T01:06:53.191+0000] {warnings.py:110} WARNING - /home/***/.local/lib/python3.12/site-packages/***/task/task_runner/standard_task_runner.py:61: DeprecationWarning: This process (pid=1429) is multi-threaded, use of fork() may lead to deadlocks in the child.
  pid = os.fork()

[2025-06-25T01:06:53.199+0000] {standard_task_runner.py:63} INFO - Started process 1431 to run task
[2025-06-25T01:06:53.198+0000] {standard_task_runner.py:90} INFO - Running: ['***', 'tasks', 'run', 'clinlytix360_pipeline', 'run_etl_cleaning', 'manual__2025-06-25T01:05:34.728263+00:00', '--job-id', '12', '--raw', '--subdir', 'DAGS_FOLDER/clinlytix_dag.py', '--cfg-path', '/tmp/tmp7d25wp65']
[2025-06-25T01:06:53.209+0000] {standard_task_runner.py:91} INFO - Job 12: Subtask run_etl_cleaning
[2025-06-25T01:06:53.681+0000] {task_command.py:426} INFO - Running <TaskInstance: clinlytix360_pipeline.run_etl_cleaning manual__2025-06-25T01:05:34.728263+00:00 [running]> on host 134949fb0e3b
[2025-06-25T01:06:54.320+0000] {taskinstance.py:2644} INFO - Exporting env vars: AIRFLOW_CTX_DAG_OWNER='ajayc' AIRFLOW_CTX_DAG_ID='clinlytix360_pipeline' AIRFLOW_CTX_TASK_ID='run_etl_cleaning' AIRFLOW_CTX_EXECUTION_DATE='2025-06-25T01:05:34.728263+00:00' AIRFLOW_CTX_TRY_NUMBER='2' AIRFLOW_CTX_DAG_RUN_ID='manual__2025-06-25T01:05:34.728263+00:00'
[2025-06-25T01:06:54.334+0000] {taskinstance.py:430} INFO - ::endgroup::
[2025-06-25T01:06:54.348+0000] {subprocess.py:63} INFO - Tmp dir root location: /tmp
[2025-06-25T01:06:54.370+0000] {subprocess.py:75} INFO - Running command: ['/usr/bin/bash', '-c', 'python /opt/***/data/scripts/etl/etl_cleaning.py']
[2025-06-25T01:06:54.459+0000] {subprocess.py:86} INFO - Output:
[2025-06-25T01:06:54.615+0000] {subprocess.py:93} INFO - python: can't open file '/opt/***/data/scripts/etl/etl_cleaning.py': [Errno 2] No such file or directory
[2025-06-25T01:06:54.631+0000] {subprocess.py:97} INFO - Command exited with return code 2
[2025-06-25T01:06:54.633+0000] {taskinstance.py:441} INFO - ::group::Post task execution logs
[2025-06-25T01:06:54.662+0000] {taskinstance.py:2890} ERROR - Task failed with exception
Traceback (most recent call last):
  File "/home/airflow/.local/lib/python3.12/site-packages/airflow/models/taskinstance.py", line 465, in _execute_task
    result = _execute_callable(context=context, **execute_callable_kwargs)
             ^^^^^^^^^^^^^^^^^^^^^^^^^^^^^^^^^^^^^^^^^^^^^^^^^^^^^^^^^^^^^
  File "/home/airflow/.local/lib/python3.12/site-packages/airflow/models/taskinstance.py", line 432, in _execute_callable
    return execute_callable(context=context, **execute_callable_kwargs)
           ^^^^^^^^^^^^^^^^^^^^^^^^^^^^^^^^^^^^^^^^^^^^^^^^^^^^^^^^^^^^
  File "/home/airflow/.local/lib/python3.12/site-packages/airflow/models/baseoperator.py", line 400, in wrapper
    return func(self, *args, **kwargs)
           ^^^^^^^^^^^^^^^^^^^^^^^^^^^
  File "/home/airflow/.local/lib/python3.12/site-packages/airflow/operators/bash.py", line 243, in execute
    raise AirflowException(
airflow.exceptions.AirflowException: Bash command failed. The command returned a non-zero exit code 2.
[2025-06-25T01:06:54.675+0000] {taskinstance.py:1205} INFO - Marking task as FAILED. dag_id=clinlytix360_pipeline, task_id=run_etl_cleaning, execution_date=20250625T010534, start_date=20250625T010653, end_date=20250625T010654
[2025-06-25T01:06:54.714+0000] {standard_task_runner.py:110} ERROR - Failed to execute job 12 for task run_etl_cleaning (Bash command failed. The command returned a non-zero exit code 2.; 1431)
[2025-06-25T01:06:54.761+0000] {local_task_job_runner.py:240} INFO - Task exited with return code 1
[2025-06-25T01:06:54.890+0000] {taskinstance.py:3482} INFO - 0 downstream tasks scheduled from follow-on schedule check
[2025-06-25T01:06:54.911+0000] {local_task_job_runner.py:222} INFO - ::endgroup::
