[2025-06-25T00:57:40.159+0000] {local_task_job_runner.py:120} INFO - ::group::Pre task execution logs
[2025-06-25T00:57:40.296+0000] {taskinstance.py:2073} INFO - Dependencies all met for dep_context=non-requeueable deps ti=<TaskInstance: clinlytix360_pipeline.run_etl_cleaning scheduled__2025-06-24T00:00:00+00:00 [queued]>
[2025-06-25T00:57:40.340+0000] {taskinstance.py:2073} INFO - Dependencies all met for dep_context=requeueable deps ti=<TaskInstance: clinlytix360_pipeline.run_etl_cleaning scheduled__2025-06-24T00:00:00+00:00 [queued]>
[2025-06-25T00:57:40.342+0000] {taskinstance.py:2303} INFO - Starting attempt 1 of 2
[2025-06-25T00:57:40.393+0000] {taskinstance.py:2327} INFO - Executing <Task(BashOperator): run_etl_cleaning> on 2025-06-24 00:00:00+00:00
[2025-06-25T00:57:40.432+0000] {warnings.py:110} WARNING - /home/***/.local/lib/python3.12/site-packages/***/task/task_runner/standard_task_runner.py:61: DeprecationWarning: This process (pid=1295) is multi-threaded, use of fork() may lead to deadlocks in the child.
  pid = os.fork()

[2025-06-25T00:57:40.447+0000] {standard_task_runner.py:63} INFO - Started process 1305 to run task
[2025-06-25T00:57:40.447+0000] {standard_task_runner.py:90} INFO - Running: ['***', 'tasks', 'run', 'clinlytix360_pipeline', 'run_etl_cleaning', 'scheduled__2025-06-24T00:00:00+00:00', '--job-id', '6', '--raw', '--subdir', 'DAGS_FOLDER/clinlytix_dag.py', '--cfg-path', '/tmp/tmpl07rkj2i']
[2025-06-25T00:57:40.461+0000] {standard_task_runner.py:91} INFO - Job 6: Subtask run_etl_cleaning
[2025-06-25T00:57:40.945+0000] {task_command.py:426} INFO - Running <TaskInstance: clinlytix360_pipeline.run_etl_cleaning scheduled__2025-06-24T00:00:00+00:00 [running]> on host 134949fb0e3b
[2025-06-25T00:57:46.625+0000] {taskinstance.py:2644} INFO - Exporting env vars: AIRFLOW_CTX_DAG_OWNER='ajayc' AIRFLOW_CTX_DAG_ID='clinlytix360_pipeline' AIRFLOW_CTX_TASK_ID='run_etl_cleaning' AIRFLOW_CTX_EXECUTION_DATE='2025-06-24T00:00:00+00:00' AIRFLOW_CTX_TRY_NUMBER='1' AIRFLOW_CTX_DAG_RUN_ID='scheduled__2025-06-24T00:00:00+00:00'
[2025-06-25T00:57:46.665+0000] {taskinstance.py:430} INFO - ::endgroup::
[2025-06-25T00:57:46.681+0000] {subprocess.py:63} INFO - Tmp dir root location: /tmp
[2025-06-25T00:57:46.687+0000] {subprocess.py:75} INFO - Running command: ['/usr/bin/bash', '-c', 'python /opt/***/data/scripts/etl/etl_cleaning.py']
[2025-06-25T00:57:46.741+0000] {subprocess.py:86} INFO - Output:
[2025-06-25T00:57:46.955+0000] {subprocess.py:93} INFO - python: can't open file '/opt/***/data/scripts/etl/etl_cleaning.py': [Errno 2] No such file or directory
[2025-06-25T00:57:46.974+0000] {subprocess.py:97} INFO - Command exited with return code 2
[2025-06-25T00:57:46.979+0000] {taskinstance.py:441} INFO - ::group::Post task execution logs
[2025-06-25T00:57:47.024+0000] {taskinstance.py:2890} ERROR - Task failed with exception
Traceback (most recent call last):
  File "/home/airflow/.local/lib/python3.12/site-packages/airflow/models/taskinstance.py", line 465, in _execute_task
    result = _execute_callable(context=context, **execute_callable_kwargs)
             ^^^^^^^^^^^^^^^^^^^^^^^^^^^^^^^^^^^^^^^^^^^^^^^^^^^^^^^^^^^^^
  File "/home/airflow/.local/lib/python3.12/site-packages/airflow/models/taskinstance.py", line 432, in _execute_callable
    return execute_callable(context=context, **execute_callable_kwargs)
           ^^^^^^^^^^^^^^^^^^^^^^^^^^^^^^^^^^^^^^^^^^^^^^^^^^^^^^^^^^^^
  File "/home/airflow/.local/lib/python3.12/site-packages/airflow/models/baseoperator.py", line 400, in wrapper
    return func(self, *args, **kwargs)
           ^^^^^^^^^^^^^^^^^^^^^^^^^^^
  File "/home/airflow/.local/lib/python3.12/site-packages/airflow/operators/bash.py", line 243, in execute
    raise AirflowException(
airflow.exceptions.AirflowException: Bash command failed. The command returned a non-zero exit code 2.
[2025-06-25T00:57:47.045+0000] {taskinstance.py:1205} INFO - Marking task as UP_FOR_RETRY. dag_id=clinlytix360_pipeline, task_id=run_etl_cleaning, execution_date=20250624T000000, start_date=20250625T005740, end_date=20250625T005747
[2025-06-25T00:57:47.141+0000] {standard_task_runner.py:110} ERROR - Failed to execute job 6 for task run_etl_cleaning (Bash command failed. The command returned a non-zero exit code 2.; 1305)
[2025-06-25T00:57:47.221+0000] {local_task_job_runner.py:240} INFO - Task exited with return code 1
[2025-06-25T00:57:47.335+0000] {taskinstance.py:3482} INFO - 0 downstream tasks scheduled from follow-on schedule check
[2025-06-25T00:57:47.343+0000] {local_task_job_runner.py:222} INFO - ::endgroup::
