[2025-06-25T01:29:44.827+0000] {task_context_logger.py:104} ERROR - Executor reports task instance <TaskInstance: clinlytix360_pipeline.run_feasibility_model manual__2025-06-25T01:21:03.001484+00:00 [queued]> finished (failed) although the task says it's queued. (Info: None) Was the task killed externally?
