[2025-06-25T00:58:55.516+0000] {local_task_job_runner.py:120} INFO - ::group::Pre task execution logs
[2025-06-25T00:58:55.730+0000] {taskinstance.py:2073} INFO - Dependencies all met for dep_context=non-requeueable deps ti=<TaskInstance: clinlytix360_pipeline.run_etl_cleaning manual__2025-06-25T00:56:47.080871+00:00 [queued]>
[2025-06-25T00:58:55.878+0000] {taskinstance.py:2073} INFO - Dependencies all met for dep_context=requeueable deps ti=<TaskInstance: clinlytix360_pipeline.run_etl_cleaning manual__2025-06-25T00:56:47.080871+00:00 [queued]>
[2025-06-25T00:58:55.948+0000] {taskinstance.py:2303} INFO - Starting attempt 2 of 2
[2025-06-25T00:58:56.096+0000] {taskinstance.py:2327} INFO - Executing <Task(BashOperator): run_etl_cleaning> on 2025-06-25 00:56:47.080871+00:00
[2025-06-25T00:58:56.143+0000] {warnings.py:110} WARNING - /home/***/.local/lib/python3.12/site-packages/***/task/task_runner/standard_task_runner.py:61: DeprecationWarning: This process (pid=1323) is multi-threaded, use of fork() may lead to deadlocks in the child.
  pid = os.fork()

[2025-06-25T00:58:56.164+0000] {standard_task_runner.py:63} INFO - Started process 1327 to run task
[2025-06-25T00:58:56.172+0000] {standard_task_runner.py:90} INFO - Running: ['***', 'tasks', 'run', 'clinlytix360_pipeline', 'run_etl_cleaning', 'manual__2025-06-25T00:56:47.080871+00:00', '--job-id', '7', '--raw', '--subdir', 'DAGS_FOLDER/clinlytix_dag.py', '--cfg-path', '/tmp/tmpbpe1ykwz']
[2025-06-25T00:58:56.190+0000] {standard_task_runner.py:91} INFO - Job 7: Subtask run_etl_cleaning
[2025-06-25T00:58:56.596+0000] {task_command.py:426} INFO - Running <TaskInstance: clinlytix360_pipeline.run_etl_cleaning manual__2025-06-25T00:56:47.080871+00:00 [running]> on host 134949fb0e3b
[2025-06-25T00:58:57.273+0000] {taskinstance.py:2644} INFO - Exporting env vars: AIRFLOW_CTX_DAG_OWNER='ajayc' AIRFLOW_CTX_DAG_ID='clinlytix360_pipeline' AIRFLOW_CTX_TASK_ID='run_etl_cleaning' AIRFLOW_CTX_EXECUTION_DATE='2025-06-25T00:56:47.080871+00:00' AIRFLOW_CTX_TRY_NUMBER='2' AIRFLOW_CTX_DAG_RUN_ID='manual__2025-06-25T00:56:47.080871+00:00'
[2025-06-25T00:58:57.279+0000] {taskinstance.py:430} INFO - ::endgroup::
[2025-06-25T00:58:57.292+0000] {subprocess.py:63} INFO - Tmp dir root location: /tmp
[2025-06-25T00:58:57.302+0000] {subprocess.py:75} INFO - Running command: ['/usr/bin/bash', '-c', 'python /opt/***/data/scripts/etl/etl_cleaning.py']
[2025-06-25T00:58:57.393+0000] {subprocess.py:86} INFO - Output:
[2025-06-25T00:58:57.574+0000] {subprocess.py:93} INFO - python: can't open file '/opt/***/data/scripts/etl/etl_cleaning.py': [Errno 2] No such file or directory
[2025-06-25T00:58:57.587+0000] {subprocess.py:97} INFO - Command exited with return code 2
[2025-06-25T00:58:57.589+0000] {taskinstance.py:441} INFO - ::group::Post task execution logs
[2025-06-25T00:58:57.627+0000] {taskinstance.py:2890} ERROR - Task failed with exception
Traceback (most recent call last):
  File "/home/airflow/.local/lib/python3.12/site-packages/airflow/models/taskinstance.py", line 465, in _execute_task
    result = _execute_callable(context=context, **execute_callable_kwargs)
             ^^^^^^^^^^^^^^^^^^^^^^^^^^^^^^^^^^^^^^^^^^^^^^^^^^^^^^^^^^^^^
  File "/home/airflow/.local/lib/python3.12/site-packages/airflow/models/taskinstance.py", line 432, in _execute_callable
    return execute_callable(context=context, **execute_callable_kwargs)
           ^^^^^^^^^^^^^^^^^^^^^^^^^^^^^^^^^^^^^^^^^^^^^^^^^^^^^^^^^^^^
  File "/home/airflow/.local/lib/python3.12/site-packages/airflow/models/baseoperator.py", line 400, in wrapper
    return func(self, *args, **kwargs)
           ^^^^^^^^^^^^^^^^^^^^^^^^^^^
  File "/home/airflow/.local/lib/python3.12/site-packages/airflow/operators/bash.py", line 243, in execute
    raise AirflowException(
airflow.exceptions.AirflowException: Bash command failed. The command returned a non-zero exit code 2.
[2025-06-25T00:58:57.644+0000] {taskinstance.py:1205} INFO - Marking task as FAILED. dag_id=clinlytix360_pipeline, task_id=run_etl_cleaning, execution_date=20250625T005647, start_date=20250625T005855, end_date=20250625T005857
[2025-06-25T00:58:57.713+0000] {standard_task_runner.py:110} ERROR - Failed to execute job 7 for task run_etl_cleaning (Bash command failed. The command returned a non-zero exit code 2.; 1327)
[2025-06-25T00:58:57.758+0000] {local_task_job_runner.py:240} INFO - Task exited with return code 1
[2025-06-25T00:58:57.873+0000] {taskinstance.py:3482} INFO - 0 downstream tasks scheduled from follow-on schedule check
[2025-06-25T00:58:57.888+0000] {local_task_job_runner.py:222} INFO - ::endgroup::
